Workbook

Sheet Cleaned Data
A1: Year | B1: Country | C1: Life expectancy at birth, total (years) | D1: GDP per capita (constant 2015 US$) | E1: Fertility rate, total (births per woman) | F1: Mortality rate, infant (per 1,000 live births) | G1: Current health expenditure per capita (current US$) | H1: School enrollment, secondary (% gross) | I1: School enrollment, tertiary (% gross) | J1: Carbon dioxide (CO2) emissions excluding LULUCF per capita (t CO2e/capita) | K1: People using at least basic sanitation services (% of population)
A2: 2000 | B2: Switzerland | C2: 79.680488 | D2: 73749.939 | E2: 1.5 | F2: 4.7 | G2: 3559.8198 | H2: 94.54991 | I2: 38.112759 | J2: 6.2358493 | K2: 99.880971
A3: 2001 | B3: Switzerland | C3: 80.180488 | D3: 74439.464 | E3: 1.38 | F3: 4.6 | G3: 3763.3845 | H3: 92.47 | I3: 39.223801 | J3: 6.3934209 | K3: 99.880969
A4: 2002 | B4: Switzerland | C4: 80.385366 | D4: 73824.385 | E4: 1.39 | F4: 4.5 | G4: 4211.7295 | H4: 92.36 | I4: 39.960289 | J4: 6.1220881 | K4: 99.880982
A5: 2003 | B5: Switzerland | C5: 80.536585 | D5: 73254.953 | E5: 1.39 | F5: 4.5 | G5: 5018.5273 | H5: 93.39 | I5: 43.050541 | J5: 6.2525812 | K5: 99.881005
A6: 2004 | B6: Switzerland | C6: 81.087805 | D6: 74718.684 | E6: 1.42 | F6: 4.4 | G6: 5608.7031 | H6: 93.16 | I6: 44.88052 | J6: 6.2830523 | K6: 99.881019
A7: 2005 | B7: Switzerland | C7: 81.236585 | D7: 76282.984 | E7: 1.42 | F7: 4.3 | G7: 5673.9399 | H7: 92.43 | I7: 45.246529 | J7: 6.3279645 | K7: 99.88104
A8: 2006 | B8: Switzerland | C8: 81.490244 | D8: 78893.808 | E8: 1.44 | F8: 4.2 | G8: 5671.9814 | H8: 93.85 | I8: 46.284779 | J8: 6.2305199 | K8: 99.881061
A9: 2007 | B9: Switzerland | C9: 81.741463 | D9: 81254.17 | E9: 1.46 | F9: 4.1 | G9: 6154.7031 | H9: 91.79 | I9: 47.815552 | J9: 5.9127146 | K9: 99.881075
A10: 2008 | B10: Switzerland | C10: 81.992683 | D10: 82481.068 | E10: 1.48 | F10: 4 | G10: 7120.6528 | H10: 93.38 | I10: 49.688881 | J10: 6.0172405 | K10: 99.881093
A11: 2009 | B11: Switzerland | C11: 82.043902 | D11: 79585.522 | E11: 1.5 | F11: 4 | G11: 7297.3799 | H11: 93.38 | I11: 50.303452 | J11: 5.7663836 | K11: 99.88111
A12: 2010 | B12: Switzerland | C12: 82.246341 | D12: 81315.423 | E12: 1.52 | F12: 3.9 | G12: 7695.688 | H12: 92.56 | I12: 52.804062 | J12: 5.9214746 | K12: 99.881129
A13: 2011 | B13: Switzerland | C13: 82.695122 | D13: 81874.336 | E13: 1.52 | F13: 3.9 | G13: 9204.8779 | H13: 93.16 | I13: 53.135281 | J13: 5.3458635 | K13: 99.884004
... A24: 2022 | B24: Switzerland | C24: 83.604878 | D24: 90605.019 | E24: 1.39 | F24: 3.5 | G24: 10963.431 | H24: 94.65 | I24: 74.152679 | J24: 3.9208106 | K24: 99.899876
A25: 2023 | B25: Switzerland | C25: 84.056098 | D25: 90084.834 | E25: 1.33 | F25: 3.5 | G25: =AVERAGEA(G22:G24) -> 10858.003 | H25: 91.1 | I25: 74.006088 | J25: 3.850286 | K25: 99.899876
A26: 2000 | B26: Australia | C26: 83.604878 | D26: 45859.516 | E26: 1.756 | F26: 5.1 | G26: 1626.7339 | H26: 99.48 | I26: =AVERAGE(I27:I29)-1 -> 110.23231 | J26: 18.596531 | K26: 99.990756
A27: 2001 | B27: Australia | C27: 84.056098 | D27: 46191.314 | E27: 1.739 | F27: 5 | G27: 1550.3739 | H27: 98.95 | I27: =AVERAGE(I28:I30)-1 -> 110.73425 | J27: 18.698505 | K27: 99.991254
A28: 2002 | B28: Australia | C28: 79.936585 | D28: 47486.278 | E28: 1.756 | F28: 4.9 | G28: 1752.939 | H28: 100.56 | I28: =AVERAGE(I29:I31)-1 -> 111.23159 | J28: 18.908281 | K28: 99.991752
A29: 2003 | B29: Australia | C29: 80.239024 | D29: 48394.127 | E29: 1.748 | F29: 4.9 | G29: 2227.1277 | H29: 97.95 | I29: =AVERAGE(I30:I32)-1 -> 111.7311 | J29: 18.666392 | K29: 99.992251
A30: 2004 | B30: Australia | C30: 80.490244 | D30: 49902.019 | E30: 1.768 | F30: 4.8 | G30: 2744.0811 | H30: 101.44 | I30: =AVERAGE(I31:I33)-1 -> 112.24005 | J30: 19.161558 | K30: 99.992749
A31: 2005 | B31: Australia | C31: 80.841463 | D31: 50853.198 | E31: 1.807 | F31: 4.8 | G31: 2995.8726 | H31: 99.22 | I31: =AVERAGE(I32:I34)-1 -> 112.72363 | J31: 19.035965 | K31: 99.993247
A32: 2006 | B32: Australia | C32: 81.041463 | D32: 51553.969 | E32: 1.908 | F32: 4.7 | G32: 3174.8687 | H32: 99.01 | I32: =AVERAGE(I33:I35)-1 -> 113.22964 | J32: 19.077402 | K32: 99.993746
A33: 2007 | B33: Australia | C33: 81.292683 | D33: 52531.761 | E33: 1.959 | F33: 4.5 | G33: 3792.8098 | H33: 100.39 | I33: =AVERAGE(I34:I36)-1 -> 113.76687 | J33: 19.237208 | K33: 99.994244
A34: 2008 | B34: Australia | C34: 81.395122 | D34: 53336.101 | E34: 1.984 | F34: 4.4 | G34: 4083.4294 | H34: 102.86 | I34: =AVERAGE(I35:I37)-1 -> 114.17438 | J34: 19.025898 | K34: 99.994743
A35: 2009 | B35: Australia | C35: 81.543902 | D35: 53237.008 | E35: 1.971 | F35: 4.2 | G35: 3989.4412 | H35: 101.29 | I35: =AVERAGE(I36:I38)-1 -> 114.74766 | J35: 18.913238 | K35: 99.995241
A36: 2010 | B36: Australia | C36: 81.695122 | D36: 53578.813 | E36: 1.928 | F36: 4 | G36: 4947.9634 | H36: 100.71 | I36: =AVERAGE(I37:I39)-1 -> 115.37858 | J36: 18.848848 | K36: 99.995739
A37: 2011 | B37: Australia | C37: 81.895122 | D37: 54111.357 | E37: 1.926 | F37: 3.8 | G37: 5876.8853 | H37: 100.68 | I37: =AVERAGE(I38:I40)-1 -> 115.39689 | J37: 18.478476 | K37: 99.996238
... A40: 2014 | B40: Australia | C40: 82.3 | D40: 56327.853 | E40: 1.826 | F40: 3.4 | G40: 6098.2544 | H40: 101.68 | I40: =AVERAGE(I41:I43)-1 -> 115.45183 | J40: 16.879485 | K40: 99.997733
A41: 2015 | B41: Australia | C41: 82.4 | D41: 56739.027 | E41: 1.814 | F41: 3.3 | G41: 5294.5723 | H41: 104.96 | I41: 119.67939 | J41: 16.81821 | K41: 99.998231
A42: 2016 | B42: Australia | C42: 82.44878 | D42: 57401.066 | E42: 1.752 | F42: 3.2 | G42: 5423.8267 | H42: 104.9 | I42: 119.68278 | J42: 16.886762 | K42: 99.998729
A43: 2017 | B43: Australia | C43: 82.5 | D43: 57750.648 | E43: 1.741 | F43: 3.2 | G43: 5780.5371 | H43: 103.61 | I43: 109.99331 | J43: 16.705729 | K43: 99.999228
A44: 2018 | B44: Australia | C44: 82.74878 | D44: 58530.782 | E44: 1.74 | F44: 3.2 | G44: 5830.1016 | H44: 103.51 | I44: 103.32209 | J44: 16.39236 | K44: 99.999726
A45: 2019 | B45: Australia | C45: 82.9 | D45: 58924.734 | E45: 1.657 | F45: 3.2 | G45: 5529.1948 | H45: 104.34 | I45: 109.75956 | J45: 16.098804 | K45: 100
A46: 2020 | B46: Australia | C46: 83.2 | D46: 58132.799 | E46: 1.581 | F46: 3.2 | G46: 5952.8906 | H46: 107.05 | I46: 110.13922 | J46: 15.303338 | K46: 100
A47: 2021 | B47: Australia | C47: 83.3 | D47: 59276.503 | E47: 1.7 | F47: 3.2 | G47: 7039.5776 | H47: 105.34 | I47: 112.68829 | J47: 14.976485 | K47: 100
A48: 2022 | B48: Australia | C48: 83.2 | D48: 61009.808 | E48: 1.63 | F48: 3.2 | G48: 6730.9951 | H48: 106.21 | I48: 106.24076 | J48: 14.410423 | K48: 100
A49: 2023 | B49: Australia | C49: 83.05122 | D49: 61598.178 | E49: 1.5 | F49: 3.1 | G49: =AVERAGE(G46:G48) -> 6574.4878 | H49: 105.39 | I49: 104.64835 | J49: 14.017916 | K49: 100
A50: 2000 | B50: Sweden | C50: 79.643902 | D50: 41561.097 | E50: 1.54 | F50: 3.4 | G50: 2173.1941 | H50: 151.75638 | I50: 67.644836 | J50: 6.5353345 | K50: 99.207098
A51: 2001 | B51: Sweden | C51: 79.795122 | D51: 42013.7 | E51: 1.57 | F51: 3.3 | G51: 2155.8542 | H51: 147.90344 | I51: 70.01152 | J51: 6.5261534 | K51: 99.193166
A52: 2002 | B52: Sweden | C52: 79.846341 | D52: 42831.019 | E52: 1.65 | F52: 3.3 | G52: 2459.0986 | H52: 144.21851 | I52: 74.741432 | J52: 6.6539585 | K52: 99.177421
...

Sheet Series - Metadata
A1: Code | B1: License Type | C1: Indicator Name | D1: Short definition | E1: Long definition | F1: Source | G1: Topic | H1: Dataset | I1: Unit of measure | J1: Periodicity | K1: Reference period | L1: Aggregation method | M1: Statistical concept and methodology | N1: Development relevance | O1: Limitations and exceptions | P1: Other notes | Q1: License URL
A2: SP.DYN.LE00.IN | B2: CC BY-4.0 | C2: Life expectancy at birth, total (years) | D2: Life expectancy at birth indicates the number of years a newborn infant would live if prevailing patterns of mortality at the time of its birth were to stay the same throughout its life. | E2: Life expectancy at birth indicates the number of years a newborn infant would live if prevailing patterns of mortality at the time of its birth were to stay the same throughout its life. | F2: World Population Prospects, United Nations (UN), uri: UN Population Division; Statistical databases and publications from national statistical offices, National statistical offices, note: Derived from male and female life expectancy at birth from sources such as statistical databases and publications from national statistical offices.; Demographic Statistics, Eurostat (ESTAT), note: Derived from male and female life expectancy at birth from sources such as Eurostat: Demographic Statistics. | G2: Health: Mortality | H2: WDI | I2: Years | J2: Annual | K2: 1960-2023 | L2: Weighted average | M2: Methodology: Life expectancy at birth is derived from life tables and is based on sex- and age-specific death rates, or derived from male and female life expectancy at birth. Statistical concept(s): Life expectancy at birth used here is the average number of years a newborn is expected to live if mortality patterns at the time of its birth remain constant in the future. It reflects the overall mortality level of a population, and summarizes the mortality pattern that prevails across all age groups in a given year. It is calculated in a period life table which provides a snapshot of a population's mortality pattern at a given time. It therefore does not reflect the mortality pattern that a person actually experiences during his/her life, which can be calculated in a cohort life table. High mortality in young age groups significantly lowers the life expectancy at birth. But if a person survives his/her childhood of high mortality, he/she may live much longer. For example, in a population with a life expectancy at birth of 50, there may be few people dying at age 50. The life expectancy at birth may be low due to the high childhood mortality so that once a person survives his/her childhood, he/she may live much longer than 50 years. | N2: Mortality rates for different age groups (infants, children, and adults) and overall mortality indicators (life expectancy at birth or survival to a given age) are important indicators of health status in a country. Because data on the incidence and prevalence of diseases are frequently unavailable, mortality rates are often used to identify vulnerable populations. And they are among the indicators most frequently used to compare socioeconomic development across countries. | O2: Annual data series from United Nations Population Division's World Population Prospects are interpolated data from 5-year period data. Therefore they may not reflect real events as much as observed data. | Q2: https://datacatalog.worldbank.org/public-licenses#cc-by
A3: NY.GDP.PCAP.KD | B3: CC BY-4.0 | C3: GDP per capita (constant 2015 US$) | D3: Gross domestic product is the total income earned through the production of goods and services in an economic territory during an accounting period. It can be measured in three different ways: using either the expenditure approach, the income approach, or the production approach. The core indicator has been divided by the general population to achieve a per capita estimate.This indicator is expressed in constant prices, meaning the series has been adjusted to account for price changes over time. The reference year for this adjustment is 2015. This indicator is expressed in United States dollars. | E3: Gross domestic product is the total income earned through the production of goods and services in an economic territory during an accounting period. It can be measured in three different ways: using either the expenditure approach, the income approach, or the production approach. The core indicator has been divided by the general population to achieve a per capita estimate.This indicator is expressed in constant prices, meaning the series has been adjusted to account for price changes over time. The reference year for this adjustment is 2015. This indicator is expressed in United States dollars. | F3: Country official statistics, National Statistical Organizations and/or Central Banks; National Accounts data files, Organisation for Economic Co-operation and Development (OECD); Staff estimates, World Bank (WB) | G3: Economic Policy & Debt: National accounts: US$ at constant 2015 prices: Aggregate indicators | H3: WDI | I3: constant 2015 US$ | J3: Annual | K3: 1960-2024 | L3: Weighted average | M3: Methodology: National accounts are compiled in accordance with international standards: System of National Accounts, 2008 or 1993 versions. Specific information on how countries compile their national accounts can be found on the IMF website: https://dsbb.imf.org/ Per capita estimates are divided by the total population. Statistical concept(s): The conceptual elements of the SNA (System of National Accounts) measure what takes place in the economy, between which agents, and for what purpose. At the heart of the SNA is the production of goods and services. These may be used for consumption in the period to which the accounts relate or may be accumulated for use in a later period. In simple terms, the amount of value added generated by production represents GDP. The income corresponding to GDP is distributed to the various agents or groups of agents as income and it is the process of distributing and redistributing income that allows one agent to consume the goods and services produced by another agent or to acquire goods and services for later consumption. The way in which the SNA captures this pattern of economic flows is to identify the activities concerned by recognizing the institutional units in the economy and by specifying the structure of accounts capturing the transactions relevant to one stage or another of the process by which goods and services are produced and ultimately consumed. | N3: This indicator is related to the national accounts, which are critical for understanding and managing a country's economy. They provide a framework for the analysis of economic performance. National accounts are the basis for estimating the Gross Domestic Product (GDP) and Gross National Income (GNI), which are the most widely used indicator of economic performance. They are essential for government policymakers, providing the data needed to design and assess fiscal and monetary policies; and are also used by businesses and investors to assess the economic climate and make investment decisions. NAS enable comparison between economies, which is crucial for international trade, investment decisions, and economic competitiveness. More specifically, this indicator is related to national accounts aggregates. Gross Domestic Product (GDP), Gross National Income (GNI), and other aggregates provide a snapshot of the size and health of an economy by measuring the total economic activity within a country. They can thus be used by policymakers to design and implement economic policies, as they reflect the overall economic performance and can indicate the need for intervention in certain areas. Aggregates also allow for comparisons between different economies, which can be useful for trade negotiations, investment decisions, and economic benchmarking. By examining aggregates over time, economists and analysts can identify trends, cycles, and potential areas of concern within an economy, and investors can use national accounts aggregates to assess the potential risks and returns of investing in a particular country. Overall, national accounts aggregates are fundamental tools for economic analysis, policy formulation, and decision-making at both the national and international levels. | Q3: https://datacatalog.worldbank.org/public-licenses#cc-by
A4: SH.XPD.EHEX.PC.CD | B4: CC BY-4.0 | C4: Health expenditure per capita (current US$) | D4: Current expenditures on health per capita expressed in current US dollars. External sources are composed of direct foreign transfers and foreign transfers distributed by government encompassing all financial inflows into the national health system from outside the country. | E4: Current expenditures on health per capita expressed in current US dollars. External sources are composed of direct foreign transfers and foreign transfers distributed by government encompassing all financial inflows into the national health system from outside the country. | F4: Global Health Expenditure database, World Health Organization (WHO), uri: http://apps.who.int/nha/database | G4: Health: Health systems | H4: WDI | I4: current US$ | J4: Annual | K4: 2000-2023 | L4: Weighted average | M4: Methodology: The Health SHA 2011 tracks all health spending in a given country over a defined period of time regardless of the entity or institution that financed and managed that spending. It generates consistent and comprehensive data on health spending in a country, which in turn can contribute to evidence-based policy-making. Statistical concept(s): The health expenditure estimates have been prepared by the World Health Organization under the framework of the System of Health Accounts 2011 (SHA 2011). | N4: Strengthening health financing is one objective of Sustainable Development Goal 3 (SDG target 3.c). The levels and trends of health expenditure data identify key issues such as weaknesses and strengths and areas that need investment, for instance additional health facilities, better health information systems, or better trained human resources. Health financing is also critical for reaching universal health coverage (UHC) defined as all people obtaining the quality health services they need without suffering financial hardship (SDG 3.8). The data on out-of-pocket spending is a key indicator with regard to financial protection and hence of progress towards UHC. | Q4: https://datacatalog.worldbank.org/public-licenses#cc-by
A5: SE.SEC.ENRR | B5: CC BY-4.0 | C5: School enrollment, secondary (% gross) | D5: Gross enrollment ratio is the ratio of total enrollment, regardless of age, to the population of the age group that officially corresponds to the level of education shown. Secondary education completes the provision of basic education that began at the primary level, and aims at laying the foundations for lifelong learning and human development, by offering more subject- or skill-oriented instruction using more specialized teachers. | E5: Gross enrollment ratio is the ratio of total enrollment, regardless of age, to the population of the age group that officially corresponds to the level of education shown. Secondary education completes the provision of basic education that began at the primary level, and aims at laying the foundations for lifelong learning and human development, by offering more subject- or skill-oriented instruction using more specialized teachers. | F5: Data API, UN Educational, Scientific and Cultural Organization (UNESCO), uri: https://databrowser.uis.unesco.org/resources, note: The data are obtained through the UIS API. Detailed documentation is available at: https://api.uis.unesco.org/api/public/documentation/, publisher: UNESCO Institute for Statistics (UIS), type: Bulk file (csv), date accessed: 2025-09-22, date published: 2025-09 | G5: Education: Participation | H5: WDI | I5: % of population in the 5-year age group immediately following primary education | J5: Annual | K5: 1970-2023 | L5: Weighted average | M5: Methodology: Gross enrollment ratio for secondary school is calculated by dividing the number of students enrolled in secondary education regardless of age by the population of the age group which officially corresponds to secondary education, and multiplying by 100. Data on education are collected by the UNESCO Institute for Statistics from official responses to its annual education survey. All the data are mapped to the International Standard Classification of Education (ISCED) to ensure the comparability of education programs at the international level. The current version was formally adopted by UNESCO Member States in 2011. Population data are drawn from the United Nations Population Division. Using a single source for population data standardizes definitions, estimations, and interpolation methods, ensuring a consistent methodology across countries and minimizing potential enumeration problems in national censuses. The reference years reflect the school year for which the data are presented. In some countries the school year spans two calendar years (for example, from September 2010 to June 2011); in these cases the reference year refers to the year in which the school year ended (2011 in the example). Statistical concept(s): Gross enrollment ratios indicate the capacity of each level of the education system, but a high ratio may reflect a substantial number of overage children enrolled in each grade because of repetition or late entry rather than a successful education system. | N5: Secondary education acts as a critical intermediary that not only builds upon the foundational knowledge acquired in primary education but also equips students for various pathways, including immediate entry into the workforce, further education in postsecondary non-tertiary institutions, or advancement to higher education. This indicator assesses the aggregate participation rate in secondary education, reflecting the education system's capacity to enroll students within a designated age group. | O5: Enrollment indicators are based on annual school surveys, but do not necessarily reflect actual attendance or dropout rates during the year. Also, the length of education differs across countries and can influence enrollment rates, although the International Standard Classification of Education (ISCED) tries to minimize the difference. For example, a shorter duration for primary education tends to increase the rate; a longer one to decrease it (in part because older children are more at risk of dropping out). Moreover, age at enrollment may be inaccurately estimated or misstated, especially in communities where registration of births is not strictly enforced. | Q5: https://datacatalog.worldbank.org/public-licenses#cc-by
A6: SE.TER.ENRR | B6: CC BY-4.0 | C6: School enrollment, tertiary (% gross) | D6: Gross enrollment ratio is the ratio of total enrollment, regardless of age, to the population of the age group that officially corresponds to the level of education shown. Tertiary education, whether or not to an advanced research qualification, normally requires, as a minimum condition of admission, the successful completion of education at the secondary level. | E6: Gross enrollment ratio is the ratio of total enrollment, regardless of age, to the population of the age group that officially corresponds to the level of education shown. Tertiary education, whether or not to an advanced research qualification, normally requires, as a minimum condition of admission, the successful completion of education at the secondary level. | F6: Data API, UN Educational, Scientific and Cultural Organization (UNESCO), uri: https://databrowser.uis.unesco.org/resources, note: The data are obtained through the UIS API. Detailed documentation is available at: https://api.uis.unesco.org/api/public/documentation/, publisher: UNESCO Institute for Statistics (UIS), type: Bulk file (csv), date accessed: 2025-09-22, date published: 2025-09 | G6: Education: Participation | H6: WDI | I6: % of population in the 5-year age group immediately following upper secondary education | J6: Annual | K6: 1970-2023 | L6: Weighted average | M6: Methodology: Gross enrollment ratio for tertiary school is calculated by dividing the number of students enrolled in tertiary education regardless of age by the population of the age group which officially corresponds to tertiary education, and multiplying by 100. Data on education are collected by the UNESCO Institute for Statistics from official responses to its annual education survey. All the data are mapped to the International Standard Classification of Education (ISCED) to ensure the comparability of education programs at the international level. The current version was formally adopted by UNESCO Member States in 2011. Population data are drawn from the United Nations Population Division. Using a single source for population data standardizes definitions, estimations, and interpolation methods, ensuring a consistent methodology across countries and minimizing potential enumeration problems in national censuses. The reference years reflect the school year for which the data are presented. In some countries the school year spans two calendar years (for example, from September 2010 to June 2011); in these cases the reference year refers to the year in which the school year ended (2011 in the example). Statistical concept(s): Gross enrollment ratios indicate the capacity of each level of the education system, but a high ratio may reflect a substantial number of overage children enrolled in each grade because of repetition or late entry rather than a successful education system. | N6: Sustainable Development Goal (SDG) target 4.3 is committed to providing equitable access to affordable and high-quality technical, vocational, and tertiary education, including university, for both women and men. This particular indicator reflects the overall capacity of the educational infrastructure to support enrolment within a specified age demographic at the tertiary level. | O6: Enrollment indicators are based on annual school surveys, but do not necessarily reflect actual attendance or dropout rates during the year. Also, the length of education differs across countries and can influence enrollment rates, although the International Standard Classification of Education (ISCED) tries to minimize the difference. For example, a shorter duration for primary education tends to increase the rate; a longer one to decrease it (in part because older children are more at risk of dropping out). Moreover, age at enrollment may be inaccurately estimated or misstated, especially in communities where registration of births is not strictly enforced. | Q6: https://datacatalog.worldbank.org/public-licenses#cc-by
A7: SP.DYN.TFRT.IN | B7: CC BY-4.0 | C7: Fertility rate, total (births per woman) | D7: Total fertility rate represents the number of children that would be born to a woman if she were to live to the end of her childbearing years and bear children in accordance with age-specific fertility rates of the specified year. | E7: Total fertility rate represents the number of children that would be born to a woman if she were to live to the end of her childbearing years and bear children in accordance with age-specific fertility rates of the specified year. | F7: World Population Prospects, United Nations (UN), publisher: UN Population Division; Statistical databases and publications from national statistical offices, National statistical offices; Demographic Statistics, Eurostat (ESTAT) | G7: Health: Reproductive health | H7: WDI | I7: Births per woman | J7: Annual | K7: 1960-2023 | L7: Weighted average | M7: Methodology: Total fertility rate is the sum of the age-specific fertility rates (multiplied by five, if the age-specific fertility rates are for 5-year age groups). Statistical concept(s): Total fertility rates are based on data on registered live births from vital registration systems or, in the absence of such systems, from censuses or sample surveys. The estimated rates are generally considered reliable measures of fertility in the recent past. Where no empirical information on age-specific fertility rates is available, a model is used to estimate the share of births to adolescents. For countries without reliable vital registration systems fertility rates are generally based on extrapolations from trends observed in censuses or surveys from earlier years. | N7: Reproductive health is a state of physical and mental well-being in relation to the reproductive system and its functions and processes. Means of achieving reproductive health include education and services during pregnancy and childbirth, safe and effective contraception, and prevention and treatment of sexually transmitted diseases. Complications of pregnancy and childbirth are the leading cause of death and disability among women of reproductive age in developing countries. | O7: Annual data series from United Nations Population Division's World Population Prospects are interpolated data from 5-year period data. Therefore they may not reflect real events as much as observed data. | P7: Relevance to gender indicator: it can indicate the status of women within households and a woman’s decision about the number and spacing of children. | Q7: https://datacatalog.worldbank.org/public-licenses#cc-by
A8: SP.DYN.IMRT.IN | B8: CC BY-4.0 | C8: Mortality rate, infant (per 1,000 live births) | D8: Infant mortality rate is the number of infants dying before reaching one year of age, per 1,000 live births in a given year. | E8: Infant mortality rate is the number of infants dying before reaching one year of age, per 1,000 live births in a given year. | F8: UN Inter-agency Group for Child Mortality Estimation, UN Children's Fund (UNICEF), uri: www.childmortality.org; World Health Organization (WHO), uri: www.childmortality.org, note: UN Inter-agency Group for Child Mortality Estimation; World Bank (WB), uri: www.childmortality.org, note: UN Inter-agency Group for Child Mortality Estimation; United Nations (UN), uri: www.childmortality.org, note: UN Inter-agency Group for Child Mortality Estimation, publisher: UN Population Division | G8: Health: Mortality | H8: WDI | I8: Per 1000 live births | J8: Annual | K8: 1960-2023 | L8: Weighted average | M8: Methodology: Estimates of neonatal, infant, and child mortality tend to vary by source and method for a given time and place. Years for available estimates also vary by country, making comparisons across countries and over time difficult. To make neonatal, infant, and child mortality estimates comparable and to ensure consistency across estimates by different agencies, the United Nations Inter-agency Group for Child Mortality Estimation (UN IGME), which comprises the United Nations Children's Fund (UNICEF), the World Health Organization (WHO), the World Bank, the United Nations Population Division, and other universities and research institutes, developed and adopted a statistical method that uses all available information to reconcile differences. The method uses statistical models to obtain a best estimate trend line by fitting a country-specific regression model of mortality rates against their reference dates. Statistical concept(s): The main sources of mortality data are vital registration systems and direct or indirect estimates based on sample surveys or censuses. A "complete" vital registration system - covering at least 90 percent of vital events in the population - is the best source of age-specific mortality data. | N8: Mortality rates for different age groups (infants, children, and adults) and overall mortality indicators (life expectancy at birth or survival to a given age) are important indicators of health status in a country. Because data on the incidence and prevalence of diseases are frequently unavailable, mortality rates are often used to identify vulnerable populations. And they are among the indicators most frequently used to compare socioeconomic development across countries. | O8: Complete vital registration systems are fairly uncommon in developing countries. Thus estimates must be obtained from sample surveys or derived by applying indirect estimation techniques to registration, census, or survey data. Survey data are subject to recall error, and surveys estimating infant/child deaths require large samples because households in which a birth has occurred during a given year cannot ordinarily be preselected for sampling. Indirect estimates rely on model life tables that may be inappropriate for the population concerned. Extrapolations based on outdated surveys may not be reliable for monitoring changes in health status or for comparative analytical work. | P8: Given that data on the incidence and prevalence of diseases are frequently unavailable, mortality rates are often used to identify vulnerable populations. Moreover, they are among the indicators most frequently used to compare socioeconomic development across countries. Under-five mortality rates are higher for boys than for girls in countries in which parental gender preferences are insignificant. Under-five mortality captures the effect of gender discrimination better than infant mortality does, as malnutrition and medical interventions have more significant impacts to this age group. Where female under-five mortality is higher, girls are likely to have less access to resources than boys. Aggregate data for LIC, UMC, LMC, HIC are computed based on the groupings for the World Bank fiscal year in which the data was released by the UN Inter-agency Group for Child Mortality Estimation. | Q8: https://datacatalog.worldbank.org/public-licenses#cc-by
A9: EN.GHG.CO2.PC.CE.AR5 | B9: CC BY-4.0 | C9: Carbon dioxide (CO2) emissions excluding LULUCF per capita (t CO2e/capita) | D9: Total annual emissions of carbon dioxide (CO2), one of the six Kyoto greenhouse gases (GHG), from the agriculture, energy, waste, and industrial sectors, excluding LULUCF, standardized to carbon dioxide equivalent values divided by the economy's population. This measure excludes GHG fluxes caused by Land Use Change Land Use and Forestry (LULUCF), as these fluxes have larger uncertainties. | E9: Total annual emissions of carbon dioxide (CO2), one of the six Kyoto greenhouse gases (GHG), from the agriculture, energy, waste, and industrial sectors, excluding LULUCF, standardized to carbon dioxide equivalent values divided by the economy's population. This measure excludes GHG fluxes caused by Land Use Change Land Use and Forestry (LULUCF), as these fluxes have larger uncertainties. | F9: EDGAR (Emissions Database for Global Atmospheric Research) Community GHG Database, Joint Research Centre (JRC) - European Commission, uri: https://edgar.jrc.ec.europa.eu/dataset_ghg2032, publisher: JRC European Commission, date published: 2024; International Energy Agency (IEA), uri: https://edgar.jrc.ec.europa.eu/dataset_ghg2032, publisher: JRC European Commission, date published: 2024 | G9: Environment: Emissions | H9: WDI | I9: t CO2e/capita | J9: Annual | K9: 1970-2023 | L9: Weighted average using population as weights | M9: Methodology: EDGAR compiles data from multiple authoritative sources, including: International Energy Agency (IEA) – Energy consumption data, United Nations Framework Convention on Climate Change (UNFCCC) – National GHG inventories, Food and Agriculture Organization (FAO) – Agricultural emissions, World Bank & National Statistics Offices – Socioeconomic and industrial data, Scientific Literature & IPCC Guidelines – Emission factors and methodologies. EDGAR follows the IPCC (Intergovernmental Panel on Climate Change) Guidelines for National Greenhouse Gas Inventories to estimate emissions. The core equation is: ?? =??×???? Where: E = Total emissions (kg, tons, or CO2-equivalent) A = Activity data (e.g., fuel consumption, production levels) EF = Emission factor (kg of pollutant per unit of activity) Depending on the pollutant, different tiers of complexity are used: Tier 1 – Default IPCC emission factors (simple estimation) Tier 2 – Country/region-specific emission factors Tier 3 – Detailed process-based models (highest accuracy) | N9: Anthropogenic (human-caused) emissions of global greenhouse gases, including carbon dioxide (CO2), methane (CH4), nitrous oxide (NO2) and F-gases, lead to an increase of the concentration of greenhouse gases in the atmosphere, which in turn causes atmospheric warming by trapping heat in the atmosphere (greenhouse gas effect). Atmospheric warming leads to climatic changes causing more frequent and extreme weather events and higher temperatures globally, leading to large impacts across the globe and particularly in developing countries that often have a limited means to adapt and build resilience. The international scientific community has warned that emissions need to decline to net zero by the middle of the 21st century to limit global warming to well below a 2deg C increase and help avoid the most consequential climate change impacts. Climate change is having a disproportionate impact on developing countries and if unabated will not only reverse past development progress and hinder poverty reduction but will also make future development more costly. Country level assessments of the potential climate change impacts on specific developing countries, performed as part of the World Bank’s Country Climate and Development Reports (CCDRs), show that climate change will have a significant impact on developing countries’ economies, ranging from about 0.5% of GDP for higher income developing countries to over 13% for the lowest income developing countries. The costs of partial adaptation to these changes will be significant as well -- ranging between 1 and 10% of developing countries’ GDP. | O9: Global GHG emissions are currently not directly measurable, but approaches for their estimation exist, and numerous sources exist to supply data for this indicator. Reputable scientific organizations produce these data for use for research, policy analysis, climate negotiations, and broader public communications. The estimated accuracy from fossil fuel combustion and industrial processes are quite high, as quantities of fossil fuels and other emissive materials (such as cement and steel) produced are well known. For these sectors, emissions estimates are roughly accurate to within 10% when aggregated to the global level and between 4% and 35% at the country level (Crippa et al., 2023). For non- combustion and non- industrial process emissions, the accuracy is lower. Agricultural emissions, for example, depend upon many factors including the type of crops grown and livestock raised, specific agricultural practices, and other climate and non-climate factors. For these emissions, the accuracy is lower—around 30% for CH4 and fluorinated gases (HFCs, PFCs, and SF6). | Q9: https://datacatalog.worldbank.org/public-licenses#cc-by
A10: SH.STA.BASS.ZS | B10: CC BY-4.0 | C10: People using at least basic sanitation services (% of population) | D10: The percentage of people using at least basic sanitation services, that is, improved sanitation facilities that are not shared with other households. This indicator encompasses both people using basic sanitation services as well as those using safely managed sanitation services. Improved sanitation facilities include flush/pour flush to piped sewer systems, septic tanks or pit latrines; ventilated improved pit latrines, compositing toilets or pit latrines with slabs. | E10: The percentage of people using at least basic sanitation services, that is, improved sanitation facilities that are not shared with other households. This indicator encompasses both people using basic sanitation services as well as those using safely managed sanitation services. Improved sanitation facilities include flush/pour flush to piped sewer systems, septic tanks or pit latrines; ventilated improved pit latrines, compositing toilets or pit latrines with slabs. | F10: WHO/UNICEF Joint Monitoring Programme (JMP) for Water Supply, Sanitation and Hygiene, World Health Organization (WHO), uri: washdata.org, date accessed: 2023-07-25, date published: 2023-07-06; UN Children's Fund (UNICEF), uri: washdata.org, note: WHO/UNICEF Joint Monitoring Programme (JMP) for Water Supply, Sanitation and Hygiene | G10: Health: Disease prevention | H10: WDI | I10: % of population | J10: Annual | K10: 2000-2022 | L10: Weighted average | M10: Methodology: The data sources for sanitation services are household surveys such as Demographic and Health Surveys (DHS) and Multiple Indicator Cluster Surveys (MICS), administrative data, census, and other datasets such as compilations by international or regional initiatives (e.g., IB-NET) or studies conducted by research institutions. Based on these national datasets, JMP estimates the proportion of the people accessing different levels of services by using linear regression. You can find the details of estimates including the rules on interpolation, extrapolation and extension in the JMP’s methodology report (https://washdata.org/reports/jmp-2017-methodology). Statistical concept(s): The JMP classifies the sanitation service levels into five tiers, ranging from the most to the least favorable: safely managed, basic, limited, unimproved, and open defecation (Reference: https://washdata.org/monitoring/sanitation). This indicator encompasses both people using basic sanitation services as well as those using safely managed sanitation services. | N10: Sanitation is fundamental to human development. Many international organizations use hygienic sanitation facilities as a measure for progress in the fight against poverty, disease, and death. Access to proper sanitation is also considered to be a human right, not a privilege, for every man, woman, and child. Sanitation generally refers to the provision of facilities and services for the safe disposal of human urine and feces. Inadequate sanitation is a major cause of disease world-wide and improving sanitation is known to have a significant beneficial impact on people's health. Basic and safely managed sanitation services can reduce diarrheal disease, and can significantly lessen the adverse health impacts of other disorders responsible for death and disease among millions of children. Diarrhea and worm infections weaken children and make them more susceptible to malnutrition and opportunistic infections like pneumonia, measles and malaria. The combined effects of inadequate sanitation, unsafe water supply and poor personal hygiene are responsible for many of childhood deaths. Every year, the failure to tackle these deficits results in severe welfare losses - wasted time, reduced productivity, ill health, impaired learning, environmental degradation and lost opportunities. Fundamental behavior changes are required before the use of improved facilities and services can be integrated into daily life. Many hygiene behaviors and habits are formed in childhood and, therefore, school health and hygiene education programs are an important part of water and sanitation improvements. Most basic sanitation technologies are not expensive to implement. However, those facing the problems of inadequate sanitation may not be aware of either the origin of their ills, or the true costs of poor sanitation and hygiene. As a result, in most of the developing countries those without sanitation are hard to convince of the need to invest scarce resources in sanitation facilities, or of the critical importance of changing long-held habits and unhygienic behaviors. Consequently, the people's representatives - governments and elected political leaders - rarely give sanitation or hygiene improvements the priority that is needed in order to tackle the massive sanitation deficit faced by the developing world. Children bear the brunt of sanitation-related impacts - their health, nutrition, growth, education, self-respect, and life opportunities suffer as a result of inadequate sanitation. Without improved sanitation, many of the current generation of children in developing countries are unlikely to develop to their full potential. Countries that don't take urgent action to redress sanitation deficiencies will find their future development and prosperity impaired. | O10: National, regional and income group estimates are made when data are available for at least 50 percent of the population. | Q10: https://datacatalog.worldbank.org/public-licenses#cc-by

Sheet Stats
B2: Variable | C2: Mean | D2: Median | E2: SD | F2: Min | G2: Max | H2: Skewness | K2: Variable | L2: Mean | M2: Median | N2: SD | O2: Min | P2: Max | Q2: Skewness
B3: Life expectancy at birth, total (years) | C3: =AVERAGE('Cleaned Data'!C2:C217) -> 73.810629 | D3: =MEDIAN('Cleaned Data'!C$2:C$217) -> 77.526829 | E3: =_xlfn.STDEV.S('Cleaned Data'!C$2:C$217) -> 10.587348 | F3: =MIN('Cleaned Data'!C$2:C$217) -> 47.937 | G3: =MAX('Cleaned Data'!C$2:C$217) -> 84.056098 | H3: =SKEW('Cleaned Data'!C$2:C$217) -> -1.2164729 | K3: Life expectancy at birth, total (years) | L3: 73.810629 | M3: 77.526829 | N3: 10.587348 | O3: 47.937 | P3: 84.056098 | Q3: -1.2164729
B4: GDP per capita (constant 2015 US$) | C4: =AVERAGE('Cleaned Data'!D2:D217) -> 27782.745 | D4: =MEDIAN('Cleaned Data'!D$2:D$217) -> 11729.414 | E4: =_xlfn.STDEV.S('Cleaned Data'!D$2:D$217) -> 27377.731 | F4: =MIN('Cleaned Data'!D$2:D$217) -> 528.49218 | G4: =MAX('Cleaned Data'!D$2:D$217) -> 90605.019 | H4: =SKEW('Cleaned Data'!D$2:D$217) -> 0.72644205 | K4: GDP per capita (constant 2015 US$) | L4: 27782.745 | M4: 11729.414 | N4: 27377.731 | O4: 528.49218 | P4: 90605.019 | Q4: 0.72644205
B5: Fertility rate, total (births per woman) | C5: =AVERAGE('Cleaned Data'!E2:E217) -> 2.5188796 | D5: =MEDIAN('Cleaned Data'!E$2:E$217) -> 1.777 | E5: =_xlfn.STDEV.S('Cleaned Data'!E$2:E$217) -> 1.7444388 | F5: =MIN('Cleaned Data'!E$2:E$217) -> 0.999 | G5: =MAX('Cleaned Data'!E$2:E$217) -> 7.249 | H5: =SKEW('Cleaned Data'!E$2:E$217) -> 1.7451798 | K5: Fertility rate, total (births per woman) | L5: 2.5188796 | M5: 1.777 | N5: 1.7444388 | O5: 0.999 | P5: 7.249 | Q5: 1.7451798
B6: Mortality rate, infant (per 1,000 live births) | C6: =AVERAGE('Cleaned Data'!F2:F217) -> 19.289352 | D6: =MEDIAN('Cleaned Data'!F$2:F$217) -> 4.9 | E6: =_xlfn.STDEV.S('Cleaned Data'!F$2:F$217) -> 25.615101 | F6: =MIN('Cleaned Data'!F$2:F$217) -> 2 | G6: =MAX('Cleaned Data'!F$2:F$217) -> 102 | H6: =SKEW('Cleaned Data'!F$2:F$217) -> 1.7279124 | K6: Mortality rate, infant (per 1,000 live births) | L6: 19.289352 | M6: 4.9 | N6: 25.615101 | O6: 2 | P6: 102 | Q6: 1.7279124
B7: Current health expenditure per capita (current US$) | C7: =AVERAGE('Cleaned Data'!G2:G217) -> 2607.1585 | D7: =MEDIAN('Cleaned Data'!G$2:G$217) -> 910.43817 | E7: =_xlfn.STDEV.S('Cleaned Data'!G$2:G$217) -> 2929.7835 | F7: =MIN('Cleaned Data'!G$2:G$217) -> 10.074523 | G7: =MAX('Cleaned Data'!G$2:G$217) -> 11262.23 | H7: =SKEW('Cleaned Data'!G$2:G$217) -> 1.0076035 | K7: Current health expenditure per capita (current US$) | L7: 2607.1585 | M7: 910.43817 | N7: 2929.7835 | O7: 10.074523 | P7: 11262.23 | Q7: 1.0076035
B8: School enrollment, secondary (% gross) | C8: =AVERAGE('Cleaned Data'!H2:H217) -> 86.913416 | D8: =MEDIAN('Cleaned Data'!H$2:H$217) -> 94.599955 | E8: =_xlfn.STDEV.S('Cleaned Data'!H$2:H$217) -> 30.860671 | F8: =MIN('Cleaned Data'!H$2:H$217) -> 10.96428 | G8: =MAX('Cleaned Data'!H$2:H$217) -> 151.75638 | H8: =SKEW('Cleaned Data'!H$2:H$217) -> -0.87911607 | K8: School enrollment, secondary (% gross) | L8: 86.913416 | M8: 94.599955 | N8: 30.860671 | O8: 10.96428 | P8: 151.75638 | Q8: -0.87911607
B9: School enrollment, tertiary (% gross) | C9: =AVERAGE('Cleaned Data'!I2:I217) -> 50.935833 | D9: =MEDIAN('Cleaned Data'!I$2:I$217) -> 53.666525 | E9: =_xlfn.STDEV.S('Cleaned Data'!I$2:I$217) -> 33.58763 | F9: =MIN('Cleaned Data'!I$2:I$217) -> 0.79297 | G9: =MAX('Cleaned Data'!I$2:I$217) -> 119.68278 | H9: =SKEW('Cleaned Data'!I$2:I$217) -> 0.12069933 | K9: School enrollment, tertiary (% gross) | L9: 50.935833 | M9: 53.666525 | N9: 33.58763 | O9: 0.79297 | P9: 119.68278 | Q9: 0.12069933
B10: Carbon dioxide (CO2) emissions excluding LULUCF per capita (t CO2e/capita) | C10: =AVERAGE('Cleaned Data'!J2:J217) -> 5.6721034 | D10: =MEDIAN('Cleaned Data'!J$2:J$217) -> 5.0178454 | E10: =_xlfn.STDEV.S('Cleaned Data'!J$2:J$217) -> 5.0685851 | F10: =MIN('Cleaned Data'!J$2:J$217) -> 0.027464402 | G10: =MAX('Cleaned Data'!J$2:J$217) -> 19.237208 | H10: =SKEW('Cleaned Data'!J$2:J$217) -> 1.2227196 | K10: Carbon dioxide (CO2) emissions excluding LULUCF per capita (t CO2e/capita) | L10: 5.6721034 | M10: 5.0178454 | N10: 5.0685851 | O10: 0.027464402 | P10: 19.237208 | Q10: 1.2227196
B11: People using at least basic sanitation services (% of population) | C11: =AVERAGE('Cleaned Data'!K2:K217) -> 77.374952 | D11: =MEDIAN('Cleaned Data'!K$2:K$217) -> 95.835621 | E11: =_xlfn.STDEV.S('Cleaned Data'!K$2:K$217) -> 31.525435 | F11: =MIN('Cleaned Data'!K$2:K$217) -> 9.6926743 | G11: =MAX('Cleaned Data'!K$2:K$217) -> 100 | H11: =SKEW('Cleaned Data'!K$2:K$217) -> -1.202862 | K11: People using at least basic sanitation services (% of population) | L11: 77.374952 | M11: 95.835621 | N11: 31.525435 | O11: 9.6926743 | P11: 100 | Q11: -1.202862
